Workbook

Sheet Epicas
A1: Historias | B1: Prioridad | C1: Estimacion
A2: HU1 | B2: Alta | C2: 4
A3: HU2 | B3: Medio | C3: 1.5
A4: HU3 | B4: Medio | C4: 1.5
A5: HU4 | B5: Alta | C5: 4
A6: HU5 | B6: Alta | C6: 5
A7: HU6 | B7: Medio | C7: 2
A8: HU7 | B8: Bajo | C8: 2
A9: HU8 | B9: Bajo | C9: 2
A10: HU9 | B10: Medio | C10: 2
A11: HU10 | B11: Bajo | C11: 1.5
A12: HU11 | B12: Bajo | C12: 2
A13: HU12 | B13: Medio | C13: 2.5
... A24: HU23 | B24: Bajo | C24: 3
A25: TOTAL | C25: =SUM(C2:C24) -> 62.5
A26: T (HORAS) | C26: 6.4
A27: Total horas | C27: =C25*C26 -> 400
A28: Semana | C28: =C27/40 -> 10

Sheet Actividades
A1: Actividades | B1: Historias | C1: Estimacion | D1: Horas reales | E1: Springs
A2: Diseño de base de datos | B2: =Epicas!A2 -> HU1 | C2: 1 | D2: =C2*Epicas!$C$26 -> 6.4 | E2: Spring 1
A3: Implementacion de base datos | B3: =Epicas!A2 -> HU1 | C3: 1 | D3: =C3*Epicas!$C$26 -> 6.4
A4: Implementar Api de catalogo de sitios turistcos | B4: =Epicas!A2 -> HU1 | C4: 1 | D4: =C4*Epicas!$C$26 -> 6.4
A5: Diseño de interfaz de catalogo de sitios turistico | B5: =Epicas!A2 -> HU1 | C5: 1 | D5: =C5*Epicas!$C$26 -> 6.4
A6: Implemtar API para ficha detallado de sitio turistico | B6: =Epicas!A3 -> HU2 | C6: 1 | D6: =C6*Epicas!$C$26 -> 6.4
A7: Diseño de interfaz de ficha detallado del sitio turistico | B7: =Epicas!A3 -> HU2 | C7: 0.5 | D7: =C7*Epicas!$C$26 -> 3.2 | E7: Spring 2
A8: Implementar API para imagenes y mapas de sitio turistico | B8: =Epicas!A4 -> HU3 | C8: 1 | D8: =C8*Epicas!$C$26 -> 6.4
A9: Diseño de interfaz de imagenes y mapas del sitios turistico | B9: =Epicas!A4 -> HU3 | C9: 0.5 | D9: =C9*Epicas!$C$26 -> 3.2
A10: Implementar API para mostrar puntos de interes | B10: =Epicas!A5 -> HU4 | C10: 1 | D10: =C10*Epicas!$C$26 -> 6.4
A11: Integracion de Mapa y posicion en tiempo real | B11: =Epicas!A5 -> HU4 | C11: 2 | D11: =C11*Epicas!$C$26 -> 12.8
A12: Implementacion de interfaz para mostrar mapa | B12: =Epicas!A5 -> HU4 | C12: 1 | D12: =C12*Epicas!$C$26 -> 6.4 | E12: Spring 3
A13: Integración de mapa y posición en tiempo real | B13: HU4 | C13: 2 | D13: =C13*Epicas!$C$26 -> 12.8
A14: Implementación de interfaz para mostrar mapa | B14: HU4 | C14: 1 | D14: =C14*Epicas!$C$26 -> 6.4
A15: Implementar descarga de mapas offline | B15: HU6 | C15: 1 | D15: =C15*Epicas!$C$26 -> 6.4
A16: Implementar API de navegación asistida (Google Maps) | B16: HU5 | C16: 2 | D16: =C16*Epicas!$C$26 -> 12.8 | E16: Spring 4
A17: Diseño de interfaz de navegación asistida | B17: HU5 | C17: 1 | D17: =C17*Epicas!$C$26 -> 6.4
A18: Implementación de narraciones guiadas | B18: HU5 | C18: 2 | D18: =C18*Epicas!$C$26 -> 12.8
A19: Implementar API para acceso offline | B19: HU6 | C19: 1 | D19: =C19*Epicas!$C$26 -> 6.4 | E19: Spring 5
A20: Implementar filtro de sitios por categoría (catálogo) | B20: HU7 | C20: 1 | D20: =C20*Epicas!$C$26 -> 6.4
A21: Diseño de interfaz de filtros | B21: HU7 | C21: 1 | D21: =C21*Epicas!$C$26 -> 6.4
A22: Implementar buscador de sitios turísticos | B22: HU8 | C22: 1 | D22: =C22*Epicas!$C$26 -> 6.4
A23: Diseño de interfaz de búsqueda | B23: HU8 | C23: 1 | D23: =C23*Epicas!$C$26 -> 6.4
A24: Implementar API para agenda de eventos turísticos | B24: HU9 | C24: 1 | D24: =C24*Epicas!$C$26 -> 6.4 | E24: Spring 6
A25: Diseño de interfaz de agenda | B25: HU9 | C25: 1 | D25: =C25*Epicas!$C$26 -> 6.4
A26: Implementar favoritos de sitios turísticos | B26: HU10 | C26: 1 | D26: =C26*Epicas!$C$26 -> 6.4
A27: Diseño de interfaz de favoritos | B27: HU10 | C27: 0.5 | D27: =C27*Epicas!$C$26 -> 3.2
A28: Implementar compartir información de sitios | B28: HU11 | C28: 1 | D28: =C28*Epicas!$C$26 -> 6.4
A29: Diseño de interfaz de reseñas | B29: HU12 | C29: 0.5 | D29: =C29*Epicas!$C$26 -> 3.2
A30: Diseño de interfaz de compartir | B30: HU11 | C30: 1 | D30: =C30*Epicas!$C$26 -> 6.4 | E30: Spring 7
A31: Implementar API de reseñas | B31: HU12 | C31: 1 | D31: =C31*Epicas!$C$26 -> 6.4
A32: Implementar API para publicar reseñas | B32: HU13 | C32: 2 | D32: =C32*Epicas!$C$26 -> 12.8
A33: Diseño de interfaz para reseñas | B33: HU13 | C33: 1 | D33: =C33*Epicas!$C$26 -> 6.4
A34: Implementar registro de usuario | B34: HU14 | C34: 1.5 | D34: =C34*Epicas!$C$26 -> 9.6 | E34: Sprint 8
A35: Diseño de interfaz de registro | B35: HU14 | C35: 1 | D35: =C35*Epicas!$C$26 -> 6.4
A36: Implementar inicio de sesión | B36: HU15 | C36: 1 | D36: =C36*Epicas!$C$26 -> 6.4
A37: Diseño de interfaz de login | B37: HU15 | C37: 1 | D37: =C37*Epicas!$C$26 -> 6.4
A38: Diseño de interfaz notificaciones | B38: HU17 | C38: 0.5 | D38: =C38*Epicas!$C$26 -> 3.2
A39: Implementar API perfil de usuario | B39: HU16 | C39: 2 | D39: =C39*Epicas!$C$26 -> 12.8 | E39: Sprint 9
A40: Diseño de interfaz perfil de usuario | B40: HU16 | C40: 1.5 | D40: =C40*Epicas!$C$26 -> 9.6
...
